Exception on /register [POST]
Traceback (most recent call last):
  File "/Users/pacheco/Documents/Practica Personal/Security Tools/Secure-File-Storage/venv/lib/python3.12/site-packages/flask/app.py", line 2070, in wsgi_app
    response = self.full_dispatch_request()
               ^^^^^^^^^^^^^^^^^^^^^^^^^^^^
  File "/Users/pacheco/Documents/Practica Personal/Security Tools/Secure-File-Storage/venv/lib/python3.12/site-packages/flask/app.py", line 1515, in full_dispatch_request
    rv = self.handle_user_exception(e)
         ^^^^^^^^^^^^^^^^^^^^^^^^^^^^^
  File "/Users/pacheco/Documents/Practica Personal/Security Tools/Secure-File-Storage/venv/lib/python3.12/site-packages/flask/app.py", line 1513, in full_dispatch_request
    rv = self.dispatch_request()
         ^^^^^^^^^^^^^^^^^^^^^^^
  File "/Users/pacheco/Documents/Practica Personal/Security Tools/Secure-File-Storage/venv/lib/python3.12/site-packages/flask/app.py", line 1499, in dispatch_request
    return self.ensure_sync(self.view_functions[rule.endpoint])(**req.view_args)
           ^^^^^^^^^^^^^^^^^^^^^^^^^^^^^^^^^^^^^^^^^^^^^^^^^^^^^^^^^^^^^^^^^^^^^
  File "/Users/pacheco/Documents/Practica Personal/Security Tools/Secure-File-Storage/app.py", line 67, in register
    user_model.create_user(username, email, hashed_password, otp_secret)
  File "/Users/pacheco/Documents/Practica Personal/Security Tools/Secure-File-Storage/models/user_model.py", line 6, in create_user
    cursor = self.mysql.connection.cursor()
             ^^^^^^^^^^^^^^^^^^^^^
  File "/Users/pacheco/Documents/Practica Personal/Security Tools/Secure-File-Storage/venv/lib/python3.12/site-packages/flask_mysqldb/__init__.py", line 94, in connection
    ctx.mysql_db = self.connect
                   ^^^^^^^^^^^^
  File "/Users/pacheco/Documents/Practica Personal/Security Tools/Secure-File-Storage/venv/lib/python3.12/site-packages/flask_mysqldb/__init__.py", line 81, in connect
    return MySQLdb.connect(**kwargs)
           ^^^^^^^^^^^^^^^^^^^^^^^^^
  File "/Users/pacheco/Documents/Practica Personal/Security Tools/Secure-File-Storage/venv/lib/python3.12/site-packages/MySQLdb/__init__.py", line 121, in Connect
    return Connection(*args, **kwargs)
           ^^^^^^^^^^^^^^^^^^^^^^^^^^^
  File "/Users/pacheco/Documents/Practica Personal/Security Tools/Secure-File-Storage/venv/lib/python3.12/site-packages/MySQLdb/connections.py", line 195, in __init__
    super().__init__(*args, **kwargs2)
MySQLdb.OperationalError: (2005, "Unknown MySQL server host 'db' (8)")
Exception on /register [POST]
Traceback (most recent call last):
  File "/Users/pacheco/Documents/Practica Personal/Security Tools/Secure-File-Storage/venv/lib/python3.12/site-packages/flask/app.py", line 2070, in wsgi_app
    response = self.full_dispatch_request()
               ^^^^^^^^^^^^^^^^^^^^^^^^^^^^
  File "/Users/pacheco/Documents/Practica Personal/Security Tools/Secure-File-Storage/venv/lib/python3.12/site-packages/flask/app.py", line 1515, in full_dispatch_request
    rv = self.handle_user_exception(e)
         ^^^^^^^^^^^^^^^^^^^^^^^^^^^^^
  File "/Users/pacheco/Documents/Practica Personal/Security Tools/Secure-File-Storage/venv/lib/python3.12/site-packages/flask/app.py", line 1513, in full_dispatch_request
    rv = self.dispatch_request()
         ^^^^^^^^^^^^^^^^^^^^^^^
  File "/Users/pacheco/Documents/Practica Personal/Security Tools/Secure-File-Storage/venv/lib/python3.12/site-packages/flask/app.py", line 1499, in dispatch_request
    return self.ensure_sync(self.view_functions[rule.endpoint])(**req.view_args)
           ^^^^^^^^^^^^^^^^^^^^^^^^^^^^^^^^^^^^^^^^^^^^^^^^^^^^^^^^^^^^^^^^^^^^^
  File "/Users/pacheco/Documents/Practica Personal/Security Tools/Secure-File-Storage/app.py", line 67, in register
    user_model.create_user(username, email, hashed_password, otp_secret)
  File "/Users/pacheco/Documents/Practica Personal/Security Tools/Secure-File-Storage/models/user_model.py", line 6, in create_user
    cursor = self.mysql.connection.cursor()
             ^^^^^^^^^^^^^^^^^^^^^
  File "/Users/pacheco/Documents/Practica Personal/Security Tools/Secure-File-Storage/venv/lib/python3.12/site-packages/flask_mysqldb/__init__.py", line 94, in connection
    ctx.mysql_db = self.connect
                   ^^^^^^^^^^^^
  File "/Users/pacheco/Documents/Practica Personal/Security Tools/Secure-File-Storage/venv/lib/python3.12/site-packages/flask_mysqldb/__init__.py", line 81, in connect
    return MySQLdb.connect(**kwargs)
           ^^^^^^^^^^^^^^^^^^^^^^^^^
  File "/Users/pacheco/Documents/Practica Personal/Security Tools/Secure-File-Storage/venv/lib/python3.12/site-packages/MySQLdb/__init__.py", line 121, in Connect
    return Connection(*args, **kwargs)
           ^^^^^^^^^^^^^^^^^^^^^^^^^^^
  File "/Users/pacheco/Documents/Practica Personal/Security Tools/Secure-File-Storage/venv/lib/python3.12/site-packages/MySQLdb/connections.py", line 195, in __init__
    super().__init__(*args, **kwargs2)
MySQLdb.OperationalError: (2005, "Unknown MySQL server host 'db' (8)")
Exception on /register [POST]
Traceback (most recent call last):
  File "/Users/pacheco/Documents/Practica Personal/Security Tools/Secure-File-Storage/venv/lib/python3.12/site-packages/flask/app.py", line 2070, in wsgi_app
    response = self.full_dispatch_request()
               ^^^^^^^^^^^^^^^^^^^^^^^^^^^^
  File "/Users/pacheco/Documents/Practica Personal/Security Tools/Secure-File-Storage/venv/lib/python3.12/site-packages/flask/app.py", line 1515, in full_dispatch_request
    rv = self.handle_user_exception(e)
         ^^^^^^^^^^^^^^^^^^^^^^^^^^^^^
  File "/Users/pacheco/Documents/Practica Personal/Security Tools/Secure-File-Storage/venv/lib/python3.12/site-packages/flask/app.py", line 1513, in full_dispatch_request
    rv = self.dispatch_request()
         ^^^^^^^^^^^^^^^^^^^^^^^
  File "/Users/pacheco/Documents/Practica Personal/Security Tools/Secure-File-Storage/venv/lib/python3.12/site-packages/flask/app.py", line 1499, in dispatch_request
    return self.ensure_sync(self.view_functions[rule.endpoint])(**req.view_args)
           ^^^^^^^^^^^^^^^^^^^^^^^^^^^^^^^^^^^^^^^^^^^^^^^^^^^^^^^^^^^^^^^^^^^^^
  File "/Users/pacheco/Documents/Practica Personal/Security Tools/Secure-File-Storage/app.py", line 67, in register
    user_model.create_user(username, email, hashed_password, otp_secret)
  File "/Users/pacheco/Documents/Practica Personal/Security Tools/Secure-File-Storage/models/user_model.py", line 6, in create_user
    cursor = self.mysql.connection.cursor()
             ^^^^^^^^^^^^^^^^^^^^^
  File "/Users/pacheco/Documents/Practica Personal/Security Tools/Secure-File-Storage/venv/lib/python3.12/site-packages/flask_mysqldb/__init__.py", line 94, in connection
    ctx.mysql_db = self.connect
                   ^^^^^^^^^^^^
  File "/Users/pacheco/Documents/Practica Personal/Security Tools/Secure-File-Storage/venv/lib/python3.12/site-packages/flask_mysqldb/__init__.py", line 81, in connect
    return MySQLdb.connect(**kwargs)
           ^^^^^^^^^^^^^^^^^^^^^^^^^
  File "/Users/pacheco/Documents/Practica Personal/Security Tools/Secure-File-Storage/venv/lib/python3.12/site-packages/MySQLdb/__init__.py", line 121, in Connect
    return Connection(*args, **kwargs)
           ^^^^^^^^^^^^^^^^^^^^^^^^^^^
  File "/Users/pacheco/Documents/Practica Personal/Security Tools/Secure-File-Storage/venv/lib/python3.12/site-packages/MySQLdb/connections.py", line 195, in __init__
    super().__init__(*args, **kwargs2)
MySQLdb.OperationalError: (2005, "Unknown MySQL server host 'db' (8)")
Exception on /register [POST]
Traceback (most recent call last):
  File "/Users/pacheco/Documents/Practica Personal/Security Tools/Secure-File-Storage/venv/lib/python3.12/site-packages/flask/app.py", line 2070, in wsgi_app
    response = self.full_dispatch_request()
               ^^^^^^^^^^^^^^^^^^^^^^^^^^^^
  File "/Users/pacheco/Documents/Practica Personal/Security Tools/Secure-File-Storage/venv/lib/python3.12/site-packages/flask/app.py", line 1515, in full_dispatch_request
    rv = self.handle_user_exception(e)
         ^^^^^^^^^^^^^^^^^^^^^^^^^^^^^
  File "/Users/pacheco/Documents/Practica Personal/Security Tools/Secure-File-Storage/venv/lib/python3.12/site-packages/flask/app.py", line 1513, in full_dispatch_request
    rv = self.dispatch_request()
         ^^^^^^^^^^^^^^^^^^^^^^^
  File "/Users/pacheco/Documents/Practica Personal/Security Tools/Secure-File-Storage/venv/lib/python3.12/site-packages/flask/app.py", line 1499, in dispatch_request
    return self.ensure_sync(self.view_functions[rule.endpoint])(**req.view_args)
           ^^^^^^^^^^^^^^^^^^^^^^^^^^^^^^^^^^^^^^^^^^^^^^^^^^^^^^^^^^^^^^^^^^^^^
  File "/Users/pacheco/Documents/Practica Personal/Security Tools/Secure-File-Storage/app.py", line 69, in register
    user_model.create_user(username, email, hashed_password, otp_secret)
  File "/Users/pacheco/Documents/Practica Personal/Security Tools/Secure-File-Storage/models/user_model.py", line 6, in create_user
    cursor = self.mysql.connection.cursor()
             ^^^^^^^^^^^^^^^^^^^^^
  File "/Users/pacheco/Documents/Practica Personal/Security Tools/Secure-File-Storage/venv/lib/python3.12/site-packages/flask_mysqldb/__init__.py", line 94, in connection
    ctx.mysql_db = self.connect
                   ^^^^^^^^^^^^
  File "/Users/pacheco/Documents/Practica Personal/Security Tools/Secure-File-Storage/venv/lib/python3.12/site-packages/flask_mysqldb/__init__.py", line 81, in connect
    return MySQLdb.connect(**kwargs)
           ^^^^^^^^^^^^^^^^^^^^^^^^^
  File "/Users/pacheco/Documents/Practica Personal/Security Tools/Secure-File-Storage/venv/lib/python3.12/site-packages/MySQLdb/__init__.py", line 121, in Connect
    return Connection(*args, **kwargs)
           ^^^^^^^^^^^^^^^^^^^^^^^^^^^
  File "/Users/pacheco/Documents/Practica Personal/Security Tools/Secure-File-Storage/venv/lib/python3.12/site-packages/MySQLdb/connections.py", line 195, in __init__
    super().__init__(*args, **kwargs2)
MySQLdb.OperationalError: (1049, "Unknown database 'secure_storage'")
New user registered: yahir@gmail.com at 2024-10-04 12:15:49.567468
User yahir successfully verified 2FA at 2024-10-04 12:18:05.626050
User yahir accessed dashboard at 2024-10-04 12:18:05.682052
User yahir logged out at 2024-10-04 12:18:12.236002
User yahir@gmail.com successfully logged in at 2024-10-04 12:19:21.946949
User yahir accessed dashboard at 2024-10-04 12:19:21.972404
User yahir logged out at 2024-10-04 12:19:27.827238
New user registered: carlos@gmail.com at 2024-10-04 12:34:59.496442
User carlos successfully verified 2FA at 2024-10-04 12:35:19.971277
User carlos accessed dashboard at 2024-10-04 12:35:19.989289
User carlos logged out at 2024-10-04 12:35:24.256313
New user registered: hoz@gmail.com at 2024-10-09 18:08:49.408669
User hoz successfully verified 2FA at 2024-10-09 18:09:12.310331
User hoz accessed dashboard at 2024-10-09 18:09:12.339612
